<?xml version='1.0' encoding='utf-8'?>
<!-- Following https://github.com/IFL-CAMP/iiwa_stack/blob/master/iiwa_description/urdf/iiwa14.xacro -->
<robot name="iiwa14">

    <link name="link0">
      <inertial>
        <origin xyz="-0.1 0 0.07" rpy="0 0 0"/>
        <mass value="5"/>
        <inertia ixx="0.05"  ixy="0"  ixz="0" iyy="0.06" iyz="0" izz="0.03" />
      </inertial>

      <visual>
        <origin xyz="0 0 0" rpy="0 0 0"/>
        <geometry>
          <mesh filename="/home/william/sai2/apps/demo/model/iiwa14/meshes/visual/link_0.obj"/>
        </geometry>
        <material name="cream_white">
          <color rgba="0.98 0.965 0.965 0.9" />
        </material>
      </visual>

<!--       <collision>
        <origin xyz="0 0 0" rpy="0 0 0"/>
        <geometry>st
          <mesh filename="../../../model/iiwa14/meshes/collision/link_0.obj"/>
        </geometry>
      </collision> -->
    </link>


    <link name="link1">
      <inertial>
        <origin xyz="0 -0.03 0.12" rpy="0 0 0"/>
        <mass value="4"/>
        <inertia ixx="0.1"  ixy="0"  ixz="0" iyy="0.09" iyz="0" izz="0.02" />
      </inertial>

      <visual>
        <origin xyz="0 0 0" rpy="0 0 0"/>
        <geometry>
          <mesh filename="/home/william/sai2/apps/demo/model/iiwa14/meshes/visual/link_1.obj"/>
        </geometry>
        <material name="cream_white">
          <color rgba="0.98 0.965 0.965 0.9" />
        </material>
      </visual>

<!--       <collision>
        <origin xyz="0 0 0" rpy="0 0 0"/>
        <geometry>
          <mesh filename="../../../model/iiwa14/meshes/collision/link_1.obj"/>
        </geometry>
      </collision> -->
    </link>


    <link name="link2">
      <inertial>
        <origin xyz="0.0003 0.059 0.042" rpy="0 0 0"/>
        <mass value="4"/>
        <inertia ixx="0.05"  ixy="0"  ixz="0" iyy="0.018" iyz="0" izz="0.044" />
      </inertial>

      <visual>
        <origin xyz="0 0 0" rpy="0 0 0"/>
        <geometry>
          <mesh filename="/home/william/sai2/apps/demo/model/iiwa14/meshes/visual/link_2.obj"/>
        </geometry>
        <material name="cream_white">
          <color rgba="0.98 0.965 0.965 0.9" />
        </material>
      </visual>

<!--       <collision>
        <origin xyz="0 0 0" rpy="0 0 0"/>
        <geometry>
          <mesh filename="../../../model/iiwa14/meshes/collision/link_2.obj"/>
        </geometry>
      </collision> -->
    </link>


    <link name="link3">
      <inertial>
        <origin xyz="0 0.03 0.13" rpy="0 0 0"/>
        <mass value="3"/>
        <inertia ixx="0.08"  ixy="0"  ixz="0" iyy="0.075" iyz="0" izz="0.01" />
      </inertial>

      <visual>
        <origin xyz="0 0 0" rpy="0 0 0"/>
        <geometry>
          <mesh filename="/home/william/sai2/apps/demo/model/iiwa14/meshes/visual/link_3.obj"/>
        </geometry>
        <material name="cream_white">
          <color rgba="0.98 0.965 0.965 0.9" />
        </material>
      </visual>

<!--       <collision>
        <origin xyz="0 0 0" rpy="0 0 0"/>
        <geometry>
          <mesh filename="../../../model/iiwa14/meshes/collision/link_3.obj"/>
        </geometry>
      </collision> -->
    </link>


    <link name="link4">
      <inertial>
        <origin xyz="0 0.067 0.034" rpy="0 0 0"/>
        <mass value="2.7"/>
        <inertia ixx="0.03"  ixy="0"  ixz="0" iyy="0.01" iyz="0" izz="0.029" />
      </inertial>

      <visual>
        <origin xyz="0 0 0" rpy="0 0 0"/>
        <geometry>
          <mesh filename="/home/william/sai2/apps/demo/model/iiwa14/meshes/visual/link_4.obj"/>
        </geometry>
        <material name="cream_white">
          <color rgba="0.98 0.965 0.965 0.9" />
        </material>
      </visual>

<!--       <collision>
        <origin xyz="0 0 0" rpy="0 0 0"/>
        <geometry>
          <mesh filename="../../../model/iiwa14/meshes/collision/link_4.obj"/>
        </geometry>
      </collision> -->
    </link>


    <link name="link5">
      <inertial>
        <origin xyz="0.0001 0.021 0.076" rpy="0 0 0"/>
        <mass value="1.7"/>
        <inertia ixx="0.02"  ixy="0"  ixz="0" iyy="0.018" iyz="0" izz="0.005" />
      </inertial>

      <visual>
        <origin xyz="0 0 0" rpy="0 0 0"/>
        <geometry>
          <mesh filename="/home/william/sai2/apps/demo/model/iiwa14/meshes/visual/link_5.obj"/>
        </geometry>
        <material name="cream_white">
          <color rgba="0.98 0.965 0.965 0.9" />
        </material>
      </visual>

<!--       <collision>
        <origin xyz="0 0 0" rpy="0 0 0"/>
        <geometry>
          <mesh filename="../../../model/iiwa14/meshes/collision/link_5.obj"/>
        </geometry>
      </collision> -->
    </link>


    <link name="link6">
      <inertial>
        <origin xyz="0 0.0006 0.0004" rpy="0 0 0"/>
        <mass value="1.8"/>
        <inertia ixx="0.005"  ixy="0"  ixz="0" iyy="0.0036" iyz="0" izz="0.0047" />
      </inertial>

      <visual>
        <origin xyz="0 0 0" rpy="0 0 0"/>
        <geometry>
          <mesh filename="/home/william/sai2/apps/demo/model/iiwa14/meshes/visual/link_6.obj"/>
        </geometry>
        <material name="cream_white">
          <color rgba="0.98 0.965 0.965 0.9" />
        </material>
      </visual>

<!--       <collision>
        <origin xyz="0 0 0" rpy="0 0 0"/>
        <geometry>
          <mesh filename="../../../model/iiwa14/meshes/collision/link_6.obj"/>
        </geometry>
      </collision> -->
    </link>


    <link name="link7">
      <inertial>
        <origin xyz="0 0 0.02" rpy="0 0 0"/>
        <mass value="0.3"/>
        <inertia ixx="0.001"  ixy="0"  ixz="0" iyy="0.001" iyz="0" izz="0.001" />
      </inertial>

      <visual>
        <origin xyz="0 0 0" rpy="0 0 0"/>
        <geometry>
          <mesh filename="/home/william/sai2/apps/demo/model/iiwa14/meshes/visual/link_7.obj"/>
        </geometry>
        <material name="cream_white">
          <color rgba="0.98 0.965 0.965 0.9" />
        </material>
      </visual>

<!--       <collision>
        <origin xyz="0 0 0" rpy="0 0 0"/>
        <geometry>
          <mesh filename="../../../model/iiwa14/meshes/collision/link_7.obj"/>
        </geometry>
      </collision> -->
    </link>

    <joint name="joint1" type="revolute">
      <parent link="link0"/>
      <child link="link1"/>
      <origin xyz="0 0 0.1575" rpy="0 0 0"/>
      <axis xyz="0 0 1"/>
      <limit lower="-2.9655" upper="2.9655" effort="320" velocity="1.4827" />
    </joint>

    <joint name="joint2" type="revolute">
      <parent link="link1"/>
      <child link="link2"/>
      <origin xyz="0 0 0.2025" rpy="1.5707 0 3.1415"/>
      <axis xyz="0 0 1"/>
      <limit lower="-2.0933" upper="2.0933" effort="320" velocity="1.4827" />
    </joint>

    <joint name="joint3" type="revolute">
      <parent link="link2"/>
      <child link="link3"/>
      <origin xyz="0 0.2045 0" rpy="1.5707 0 3.1415"/>
      <axis xyz="0 0 1"/>
      <limit lower="-2.9655" upper="2.9655" effort="176" velocity="1.7444" />
    </joint>

    <joint name="joint4" type="revolute">
      <parent link="link3"/>
      <child link="link4"/>
      <origin xyz="0 0 0.2155" rpy="1.5707 0 0"/>
      <axis xyz="0 0 1"/>
      <limit lower="-2.0933" upper="2.0933" effort="176" velocity="1.3083" />
    </joint>

    <joint name="joint5" type="revolute">
      <parent link="link4"/>
      <child link="link5"/>
      <origin xyz="0 0.1845 0" rpy="-1.5707 3.1415 0"/>
      <axis xyz="0 0 1"/>
      <limit lower="-2.9655" upper="2.9655" effort="110" velocity="2.2677" />
    </joint>

    <joint name="joint6" type="revolute">
      <parent link="link5"/>
      <child link="link6"/>
      <origin xyz="0 0 0.2155" rpy="1.5707 0 0"/>
      <axis xyz="0 0 1"/>
      <limit lower="-2.0933" upper="2.0933" effort="40" velocity="2.3550" />
    </joint>

    <joint name="joint7" type="revolute">
      <parent link="link6"/>
      <child link="link7"/>
      <origin xyz="0 0.081 0" rpy="-1.5707 3.1415 0"/>
      <axis xyz="0 0 1"/>
      <limit lower="-3.0527" upper="3.0527" effort="40" velocity="2.3550" />
    </joint>

</robot>
